Workbook
Name carbon: 'MER Environment Data'!$A$11:$O$62
Name carbon_col: 'MER Environment Data'!$A$11:$O$11
Name code: 'EIA SEDS Codes'!$B$11:$D$770
Name code_col: 'EIA SEDS Codes'!$B$11:$D$11
Name emissions: Calibration!$A$6:$A$55
Name emissions_col: Calibration!$A$4:$A$4
Name forstata_cd: #REF!
Name forstata_cd_col: #REF!
Name forstata_ee: #REF!
Name forstata_ee_col: #REF!
Name gdp: 'MER GDP Data'!$A$11:$H$86
Name gdp_col: 'MER GDP Data'!$A$11:$H$11
Name sedsAnalysis: 'Carbon Intensity'!$A$4:$AO$54
Name sedsAnalysis: 'Intermediate (old)'!$A$5:$AT$64
Name sedsAnalysis: 'SEDS Data Processed'!$A$5:$DC$64
Name sedsAnalysis_col: 'Carbon Intensity'!#REF!
Name sedsAnalysis_col: 'Intermediate (old)'!$A$5:$AT$5
Name sedsAnalysis_col: 'SEDS Data Processed'!$A$5:$DC$5
Name sedsPE: 'SEDS Prices and Expenditures'!$C$1:$BC$310
Name sedsPE_col: 'SEDS Prices and Expenditures'!$C$1:$BC$1
Name sedsQ: 'SEDS Quantities'!$C$1:$BM$432
Name sedsQ_col: 'SEDS Quantities'!$C$1:$BM$1

Sheet Audit
A1: Last updated: 12/3/23
A3: Data
A4: Tab | B4: Description | C4: Source | D4: Link | E4: Access Date
A5: MER GDP Data | B5: Macroeconomic data reported by EIA. Originally from EIA | C5: MER Table C1, "Population, U.S. gross domestic product, and U.S. gross output" | D5: https://www.eia.gov/totalenergy/data/monthly/ | E5: 45212
A6: MER Quantity Data | B6: Primary Energy Use data reported by EIA. | C6: MER Table 1.1, "Primary energy overview" | D6: https://www.eia.gov/totalenergy/data/monthly/ | E6: 45212
A7: MER Environment Data | B7: Carbon emissions report by EIA. | C7: MER Table 11.1, "Carbon dioxide emissions from energy consumption: by source") | D7: https://www.eia.gov/totalenergy/data/monthly/ | E7: 45212
A9: Results
A10: Tab | B10: Description
A11: Calibration | B11: Calculates: (1) growth rate of CO2/Zd (cell G6) and (2) Climate damages as a % of output in 2020 (cell K13).

Sheet Results -->

Sheet Calibration
A1: Dataset: | C1: carbon
A2: Variable: | C2: Total Energy CO2 Emissions
A4: Year | B4: Total Fossil | C4: CO2 Emissions | D4: Carbon intensity of fossil energy
B5: (Quadrillion Btu) | C5: =VLOOKUP("unit",INDIRECT(C$1),MATCH(C$2,INDIRECT(C$1&"_col"),),) -> (Million Metric Tons of Carbon Dioxide) | D5: Ratio | F5: Growth Rate Calculation | J5: SCC Calculation
A6: 1973 | B6: ='MER Quantity Data'!E37 -> 61.592952 | C6: =VLOOKUP($A6,INDIRECT(C$1),MATCH(C$2,INDIRECT(C$1&"_col"),),) -> 4720.916 | D6: =IF(ISERROR(C6/B6),"",C6/B6) -> 76.647016 | F6: Annual: | G6: {=LOGEST(D33:D54)} -> 0.97271173 | H6: 98.109085 | J6: Variable | K6: Value | L6: Unit | M6: Notes
A7: 1974 | B7: ='MER Quantity Data'!E38 -> 60.152492 | C7: =VLOOKUP($A7,INDIRECT(C$1),MATCH(C$2,INDIRECT(C$1&"_col"),),) -> 4561.017 | D7: =IF(ISERROR(C7/B7),"",C7/B7) -> 75.82424 | J7: SCC in $2020 | K7: 185 | L7: dollars/tonne of CO2 | M7: Source: Rennert et al 2022 (full citation in paper)
A8: 1975 | B8: ='MER Quantity Data'!E39 -> 59.140884 | C8: =VLOOKUP($A8,INDIRECT(C$1),MATCH(C$2,INDIRECT(C$1&"_col"),),) -> 4427.937 | D8: =IF(ISERROR(C8/B8),"",C8/B8) -> 74.870998 | J8: 2020 Deflator | K8: ='MER GDP Data'!G84 -> 1.13784 | L8: $2020/$2012
A9: 1976 | B9: ='MER Quantity Data'!E40 -> 59.499382 | C9: =VLOOKUP($A9,INDIRECT(C$1),MATCH(C$2,INDIRECT(C$1&"_col"),),) -> 4694.612 | D9: =IF(ISERROR(C9/B9),"",C9/B9) -> 78.901862 | J9: SCC in $2012 | K9: =K7/K8 -> 162.58876 | L9: dollars/tonne of CO2
A10: 1977 | B10: ='MER Quantity Data'!E41 -> 60.374687 | C10: =VLOOKUP($A10,INDIRECT(C$1),MATCH(C$2,INDIRECT(C$1&"_col"),),) -> 4835.148 | D10: =IF(ISERROR(C10/B10),"",C10/B10) -> 80.085682 | J10: Emissions in 2020 | K10: ='MER Environment Data'!O60*1000000 -> 4580512000 | L10: tonnes
A11: 1978 | B11: ='MER Quantity Data'!E42 -> 61.069714 | C11: =VLOOKUP($A11,INDIRECT(C$1),MATCH(C$2,INDIRECT(C$1&"_col"),),) -> 4884.113 | D11: =IF(ISERROR(C11/B11),"",C11/B11) -> 79.976025 | J11: Damage in 2020 | K11: =K10*K9 -> 7.4473979e+11 | L11: dollars
A12: 1979 | B12: ='MER Quantity Data'!E43 -> 63.85871 | C12: =VLOOKUP($A12,INDIRECT(C$1),MATCH(C$2,INDIRECT(C$1&"_col"),),) -> 4949.897 | D12: =IF(ISERROR(C12/B12),"",C12/B12) -> 77.513263 | J12: Y in 2020 | K12: ='MER GDP Data'!F84*1000000000 -> 18509100000000 | L12: dollars
A13: 1980 | B13: ='MER Quantity Data'!E44 -> 65.163631 | C13: =VLOOKUP($A13,INDIRECT(C$1),MATCH(C$2,INDIRECT(C$1&"_col"),),) -> 4756.328 | D13: =IF(ISERROR(C13/B13),"",C13/B13) -> 72.990531 | J13: Fraction of Y Lost | K13: =K11/K12 -> 0.040236413
A14: 1981 | B14: ='MER Quantity Data'!E45 -> 65.011741 | C14: =VLOOKUP($A14,INDIRECT(C$1),MATCH(C$2,INDIRECT(C$1&"_col"),),) -> 4636.684 | D14: =IF(ISERROR(C14/B14),"",C14/B14) -> 71.320717
A15: 1982 | B15: ='MER Quantity Data'!E46 -> 64.292891 | C15: =VLOOKUP($A15,INDIRECT(C$1),MATCH(C$2,INDIRECT(C$1&"_col"),),) -> 4404.478 | D15: =IF(ISERROR(C15/B15),"",C15/B15) -> 68.506454
A16: 1983 | B16: ='MER Quantity Data'!E47 -> 61.639884 | C16: =VLOOKUP($A16,INDIRECT(C$1),MATCH(C$2,INDIRECT(C$1&"_col"),),) -> 4383.992 | D16: =IF(ISERROR(C16/B16),"",C16/B16) -> 71.122652
A17: 1984 | B17: ='MER Quantity Data'!E48 -> 66.465843 | C17: =VLOOKUP($A17,INDIRECT(C$1),MATCH(C$2,INDIRECT(C$1&"_col"),),) -> 4612.908 | D17: =IF(ISERROR(C17/B17),"",C17/B17) -> 69.402686
A18: 1985 | B18: ='MER Quantity Data'!E49 -> 65.595457 | C18: =VLOOKUP($A18,INDIRECT(C$1),MATCH(C$2,INDIRECT(C$1&"_col"),),) -> 4605.41 | D18: =IF(ISERROR(C18/B18),"",C18/B18) -> 70.209283
A19: 1986 | B19: ='MER Quantity Data'!E50 -> 64.889589 | C19: =VLOOKUP($A19,INDIRECT(C$1),MATCH(C$2,INDIRECT(C$1&"_col"),),) -> 4615.724 | D19: =IF(ISERROR(C19/B19),"",C19/B19) -> 71.131965
A20: 1987 | B20: ='MER Quantity Data'!E51 -> 65.659019 | C20: =VLOOKUP($A20,INDIRECT(C$1),MATCH(C$2,INDIRECT(C$1&"_col"),),) -> 4775.616 | D20: =IF(ISERROR(C20/B20),"",C20/B20) -> 72.733587
A21: 1988 | B21: ='MER Quantity Data'!E52 -> 67.255507 | C21: =VLOOKUP($A21,INDIRECT(C$1),MATCH(C$2,INDIRECT(C$1&"_col"),),) -> 4998.283 | D21: =IF(ISERROR(C21/B21),"",C21/B21) -> 74.317825
A22: 1989 | B22: ='MER Quantity Data'!E53 -> 67.256001 | C22: =VLOOKUP($A22,INDIRECT(C$1),MATCH(C$2,INDIRECT(C$1&"_col"),),) -> 5084.633 | D22: =IF(ISERROR(C22/B22),"",C22/B22) -> 75.601179
A23: 1990 | B23: ='MER Quantity Data'!E54 -> 68.490245 | C23: =VLOOKUP($A23,INDIRECT(C$1),MATCH(C$2,INDIRECT(C$1&"_col"),),) -> 5037.975 | D23: =IF(ISERROR(C23/B23),"",C23/B23) -> 73.557556
A24: 1991 | B24: ='MER Quantity Data'!E55 -> 68.154712 | C24: =VLOOKUP($A24,INDIRECT(C$1),MATCH(C$2,INDIRECT(C$1&"_col"),),) -> 4990.804 | D24: =IF(ISERROR(C24/B24),"",C24/B24) -> 73.227571
A25: 1992 | B25: ='MER Quantity Data'!E56 -> 68.025635 | C25: =VLOOKUP($A25,INDIRECT(C$1),MATCH(C$2,INDIRECT(C$1&"_col"),),) -> 5088.755 | D25: =IF(ISERROR(C25/B25),"",C25/B25) -> 74.806431
... A54: 2021 | B54: ='MER Quantity Data'!E85 -> 93.829441 | C54: =VLOOKUP($A54,INDIRECT(C$1),MATCH(C$2,INDIRECT(C$1&"_col"),),) -> 4903.572 | D54: =IF(ISERROR(C54/B54),"",C54/B54) -> 52.260484
A55: 2022

Sheet Data -->

Sheet MER GDP Data
A1: U.S. Energy Information Administration
A2: September 2023 Monthly Energy Review
A4: =HYPERLINK("http://www.eia.gov/totalenergy/data/monthly/dataunits.cfm","Note: Information about data precision.") -> Note: Information about data precision.
A6: Release Date: September 26, 2023
A7: Next Update: October 26, 2023
A9: Table C1 Population, U.S. Gross Domestic Product, and U.S. Gross Output
A11: Year | B11: Total Resident Population, United States | C11: Total Resident Population, World | D11: United States Share of World Population | E11: U.S. Gross Domestic Product, Nominal | F11: U.S. Gross Domestic Product, Real | G11: U.S. Gross Domestic Product Implicit Price Deflator | H11: U.S. Gross Output, Nominal Dollars
A12: units | B12: (Million people) | C12: (Million people) | D12: (Percent) | E12: (Billion Dollars) | F12: (Billion chained (2012) dollars) | G12: (2012 = 1.00000) | H12: (Billion Dollars)
A13: 1949 | B13: 149.2 | C13: Not Available | D13: Not Available | E13: 272.5 | F13: 2108 | G13: 0.12926 | H13: 510.3
A14: 1950 | B14: 152.3 | C14: 2557.6 | D14: 6 | E14: 299.8 | F14: 2291.1 | G14: 0.13087 | H14: 577.8
A15: 1951 | B15: 154.9 | C15: 2594.9 | D15: 6 | E15: 346.9 | F15: 2475.4 | G15: 0.14014 | H15: 654.6
A16: 1952 | B16: 157.6 | C16: 2636.8 | D16: 6 | E16: 367.3 | F16: 2576.7 | G16: 0.14256 | H16: 686
A17: 1953 | B17: 160.2 | C17: 2682.1 | D17: 6 | E17: 389.2 | F17: 2697.5 | G17: 0.14429 | H17: 739.2
A18: 1954 | B18: 163 | C18: 2730.2 | D18: 6 | E18: 390.5 | F18: 2681.9 | G18: 0.14563 | H18: 739.9
A19: 1955 | B19: 165.9 | C19: 2782.1 | D19: 6 | E19: 425.5 | F19: 2873.2 | G19: 0.14809 | H19: 802.6
A20: 1956 | B20: 168.9 | C20: 2835.3 | D20: 6 | E20: 449.4 | F20: 2934.4 | G20: 0.15313 | H20: 841.8
A21: 1957 | B21: 172 | C21: 2891.4 | D21: 5.9 | E21: 474 | F21: 2996.2 | G21: 0.15821 | H21: 875.5
A22: 1958 | B22: 174.9 | C22: 2948.2 | D22: 5.9 | E22: 481.2 | F22: 2974 | G22: 0.16181 | H22: 897.5
A23: 1959 | B23: 177.8 | C23: 3000.7 | D23: 5.9 | E23: 521.7 | F23: 3180.2 | G23: 0.16403 | H23: 978.9
A24: 1960 | B24: 180.7 | C24: 3043 | D24: 5.9 | E24: 542.4 | F24: 3262.1 | G24: 0.16627 | H24: 1006
A25: 1961 | B25: 183.7 | C25: 3084.1 | D25: 6 | E25: 562.2 | F25: 3345.7 | G25: 0.16804 | H25: 1029.7
... A86: 2022 | B86: 333.3 | C86: 7905.3 | D86: 4.2 | E86: 25462.7 | F86: 20014.1 | G86: 1.27224 | H86: 45962.8

Sheet MER Quantity Data
A1: U.S. Energy Information Administration
A2: September 2023 Monthly Energy Review
A4: =HYPERLINK("http://www.eia.gov/totalenergy/data/monthly/dataunits.cfm","Note: Information about data precision.") -> Note: Information about data precision.
A6: Release Date: September 26, 2023
A7: Next Update: October 26, 2023
A9: Table 1.1 Primary Energy Overview
A11: Annual Total | B11: Total Fossil Fuels Production | C11: Nuclear Electric Power Production | D11: Total Renewable Energy Production | E11: Total Primary Energy Production | F11: Primary Energy Imports | G11: Primary Energy Exports | H11: Primary Energy Net Imports | I11: Primary Energy Stock Change and Other | J11: Total Fossil Fuels Consumption | K11: Nuclear Electric Power Consumption | L11: Total Renewable Energy Consumption | M11: Total Primary Energy Consumption
B12: (Quadrillion Btu) | C12: (Quadrillion Btu) | D12: (Quadrillion Btu) | E12: (Quadrillion Btu) | F12: (Quadrillion Btu) | G12: (Quadrillion Btu) | H12: (Quadrillion Btu) | I12: (Quadrillion Btu) | J12: (Quadrillion Btu) | K12: (Quadrillion Btu) | L12: (Quadrillion Btu) | M12: (Quadrillion Btu)
A13: 1949 | B13: 28.740479 | C13: 0 | D13: 1.872627 | E13: 30.613106 | F13: 1.448158 | G13: 1.59176 | H13: -0.143602 | I13: 0.396915 | J13: 28.988371 | K13: 0 | L13: 1.872627 | M13: 30.866419
A14: 1950 | B14: 32.553205 | C14: 0 | D14: 1.906525 | E14: 34.45973 | F14: 1.912887 | G14: 1.465322 | H14: 0.447565 | I14: -1.379921 | J14: 31.614755 | K14: 0 | L14: 1.906525 | M14: 33.527374
A15: 1951 | B15: 35.782118 | C15: 0 | D15: 1.8908 | E15: 37.672919 | F15: 1.892425 | G15: 2.621545 | H15: -0.729119 | I15: -1.057801 | J15: 33.987736 | K15: 0 | L15: 1.8908 | M15: 35.885997
A16: 1952 | B16: 34.964662 | C16: 0 | D16: 1.848694 | E16: 36.813356 | F16: 2.145984 | G16: 2.365131 | H16: -0.219147 | I16: -0.959659 | J16: 33.778116 | K16: 0 | L16: 1.848694 | M16: 35.63455
A17: 1953 | B17: 35.338361 | C17: 0 | D17: 1.792616 | E17: 37.130976 | F17: 2.313042 | G17: 1.866013 | H17: 0.447029 | I17: -0.976252 | J17: 34.802286 | K17: 0 | L17: 1.792616 | M17: 36.601753
A18: 1954 | B18: 33.752228 | C18: 0 | D18: 1.775242 | E18: 35.52747 | F18: 2.347876 | G18: 1.696301 | H18: 0.651575 | I18: -0.544362 | J18: 33.851458 | K18: 0 | L18: 1.775242 | M18: 35.634683
A19: 1955 | B19: 37.346797 | C19: 0 | D19: 1.82074 | E19: 39.167537 | F19: 2.789908 | G19: 2.285508 | H19: 0.504399 | I19: -0.4569 | J19: 37.380419 | K19: 0 | L19: 1.82074 | M19: 39.215038
A20: 1956 | B20: 39.75301 | C20: 0 | D20: 1.843178 | E20: 41.596188 | F20: 3.206741 | G20: 2.945377 | H20: 0.261364 | I20: -1.143199 | J20: 38.855656 | K20: 0 | L20: 1.843178 | M20: 40.714353
A21: 1957 | B21: 40.11844 | C21: 0.000112 | D21: 1.788598 | E21: 41.90715 | F21: 3.528983 | G21: 3.439441 | H21: 0.089541 | I21: -1.303379 | J21: 38.892315 | K21: 0.000112 | L21: 1.788598 | M21: 40.693313
A22: 1958 | B22: 37.205122 | C22: 0.001915 | D22: 1.813136 | E22: 39.020172 | F22: 3.884371 | G22: 2.049839 | H22: 1.834533 | I22: -0.347378 | J22: 38.680955 | K22: 0.001915 | L22: 1.813136 | M22: 40.507326
A23: 1959 | B23: 39.032065 | C23: 0.002187 | D23: 1.834493 | E23: 40.868746 | F23: 4.076278 | G23: 1.533808 | H23: 2.54247 | I23: -1.055097 | J23: 40.507312 | K23: 0.002187 | L23: 1.834493 | M23: 42.356119
A24: 1960 | B24: 39.854831 | C24: 0.006026 | D24: 1.829873 | E24: 41.69073 | F24: 4.187626 | G24: 1.477475 | H24: 2.710151 | I24: -0.45848 | J24: 42.091028 | K24: 0.006026 | L24: 1.829873 | M24: 43.942401
... A86: 2022 | B86: 81.592463 | C86: 8.046361 | D86: 8.304253 | E86: 97.943077 | F86: 21.506533 | G86: 27.338551 | H86: -5.832018 | I86: 2.681597 | J86: 78.517967 | K86: 8.046361 | L86: 8.087707 | M86: 94.792656

Sheet MER Environment Data
A1: U.S. Energy Information Administration
A2: September 2023 Monthly Energy Review
A4: =HYPERLINK("http://www.eia.gov/totalenergy/data/monthly/dataunits.cfm","Note: Information about data precision.") -> Note: Information about data precision.
A6: Release Date: September 26, 2023
A7: Next Update: October 26, 2023
A9: Table 11.1 Carbon Dioxide Emissions From Energy Consumption by Source
A11: Annual Total | B11: Coal, Including Coal Coke Net Imports, CO2 Emissions | C11: Natural Gas, Excluding Supplemental Gaseous Fuels, CO2 Emissions | D11: Aviation Gasoline CO2 Emissions | E11: Distillate Fuel Oil, Excluding Biodiesel, CO2 Emissions | F11: Hydrocarbon Gas Liquids CO2 Emissions | G11: Jet Fuel CO2 Emissions | H11: Kerosene CO2 Emissions | I11: Lubricants CO2 Emissions | J11: Motor Gasoline, Excluding Ethanol, CO2 Emissions | K11: Petroleum Coke CO2 Emissions | L11: Residual Fuel Oil CO2 Emissions | M11: Other Petroleum Products CO2 Emissions | N11: Petroleum, Excluding Biofuels, CO2 Emissions | O11: Total Energy CO2 Emissions
A12: unit | B12: (Million Metric Tons of Carbon Dioxide) | C12: (Million Metric Tons of Carbon Dioxide) | D12: (Million Metric Tons of Carbon Dioxide) | E12: (Million Metric Tons of Carbon Dioxide) | F12: (Million Metric Tons of Carbon Dioxide) | G12: (Million Metric Tons of Carbon Dioxide) | H12: (Million Metric Tons of Carbon Dioxide) | I12: (Million Metric Tons of Carbon Dioxide) | J12: (Million Metric Tons of Carbon Dioxide) | K12: (Million Metric Tons of Carbon Dioxide) | L12: (Million Metric Tons of Carbon Dioxide) | M12: (Million Metric Tons of Carbon Dioxide) | N12: (Million Metric Tons of Carbon Dioxide) | O12: (Million Metric Tons of Carbon Dioxide)
A13: 1973 | B13: 1220.645 | C13: 1174.859 | D13: 5.769 | E13: 485.041 | F13: 79.54 | G13: 154.162 | H13: 32.747 | I13: 13.29 | J13: 911.373 | K13: 55.137 | L13: 486.2 | M13: 102.153 | N13: 2325.412 | O13: 4720.916
A14: 1974 | B14: 1199.284 | C14: 1134.215 | D14: 5.659 | E14: 462.397 | F14: 76.569 | G14: 144.427 | H14: 26.704 | I14: 12.728 | J14: 892.676 | K14: 50.473 | L14: 454.598 | M14: 101.288 | N14: 2227.518 | O14: 4561.017
A15: 1975 | B15: 1195.032 | C15: 1042.504 | D15: 4.909 | E15: 447.176 | F15: 72.841 | G15: 145.616 | H15: 24.064 | I15: 11.268 | J15: 911.4 | K15: 52.102 | L15: 424.097 | M15: 96.927 | N15: 2190.401 | O15: 4427.937
A16: 1976 | B16: 1281.173 | C16: 1062.805 | D16: 4.663 | E16: 492.737 | F16: 75.039 | G16: 144.116 | H16: 25.695 | I16: 12.518 | J16: 955.397 | K16: 51.548 | L16: 483.828 | M16: 105.093 | N16: 2350.634 | O16: 4694.612
A17: 1977 | B17: 1315.721 | C17: 1041.058 | D17: 4.862 | E17: 525.595 | F17: 73.753 | G17: 151.264 | H17: 26.542 | I17: 13.097 | J17: 979.978 | K17: 56.553 | L17: 529.037 | M17: 117.689 | N17: 2478.369 | O17: 4835.148
A18: 1978 | B18: 1314.183 | C18: 1045.228 | D18: 4.94 | E18: 538.161 | F18: 71.192 | G18: 153.919 | H18: 26.575 | I18: 14.065 | J18: 1012.064 | K18: 54.057 | L18: 520.702 | M18: 129.028 | N18: 2524.703 | O18: 4884.113
A19: 1979 | B19: 1427.458 | C19: 1080.485 | D19: 4.861 | E19: 519.151 | F19: 81.865 | G19: 156.752 | H19: 28.454 | I19: 14.717 | J19: 960.537 | K19: 52.031 | L19: 486.868 | M19: 136.719 | N19: 2441.955 | O19: 4949.897
A20: 1980 | B20: 1453.794 | C20: 1058.054 | D20: 4.449 | E20: 450.809 | F20: 78.025 | G20: 155.811 | H20: 24.056 | I20: 13.105 | J20: 900.745 | K20: 50.116 | L20: 433.295 | M20: 134.069 | N20: 2244.48 | O20: 4756.328
A21: 1981 | B21: 1502.932 | C21: 1032.089 | D21: 3.89 | E21: 443.648 | F21: 77.922 | G21: 146.691 | H21: 19.215 | I21: 12.569 | J21: 899.511 | K21: 53.167 | L21: 359.671 | M21: 85.379 | N21: 2101.662 | O21: 4636.684
A22: 1982 | B22: 1449.085 | C22: 960.901 | D22: 3.248 | E22: 418.891 | F22: 79.278 | G22: 147.354 | H22: 19.488 | I22: 11.461 | J22: 892.918 | K22: 52.375 | L22: 295.693 | M22: 73.785 | N22: 1994.492 | O22: 4404.478
A23: 1983 | B23: 1504.796 | C23: 901.094 | D23: 3.296 | E23: 422.074 | F23: 73.586 | G23: 152.29 | H23: 19.235 | I23: 12 | J23: 904.238 | K23: 48.327 | L23: 244.771 | M23: 98.285 | N23: 1978.102 | O23: 4383.992
A24: 1984 | B24: 1616.103 | C24: 962.252 | D24: 3.034 | E24: 447.566 | F24: 79.848 | G24: 171.696 | H24: 17.505 | I24: 12.796 | J24: 916.35 | K24: 52.421 | L24: 236.546 | M24: 96.791 | N24: 2034.553 | O24: 4612.908
... A62: 2022 | B62: 934.698 | C62: 1745.629 | D62: 1.543 | E62: 619.456 | F62: 95.848 | G62: 233.162 | H62: 0.795 | I62: 9.071 | J62: 1065.004 | K62: 56.758 | L62: 56.728 | M62: 111.158 | N62: 2249.523 | O62: 4940.825

Sheet To be deleted -->

Sheet Carbon Intensity
A1: dataset: | C1: carbon
C2: Total Energy CO2 Emissions
B4: Total Fossil | C4: CO2 Emissions | D4: Carbon intensity of fossil energy
B5: (Quadrillion Btu) | C5: =VLOOKUP("unit",INDIRECT(C$1),MATCH(C$2,INDIRECT(C$1&"_col"),),) -> (Million Metric Tons of Carbon Dioxide) | D5: Ratio | F5: Growth Rate Calculation
A6: 1973 | B6: ='MER Quantity Data'!B37 -> 58.207232 | C6: =VLOOKUP($A6,INDIRECT(C$1),MATCH(C$2,INDIRECT(C$1&"_col"),),) -> 4720.916 | D6: =IF(ISERROR(C6/B6),"",C6/B6) -> 81.105317 | F6: Annual: | G6: {=LOGEST(D33:D54)} -> 0.97271264 | H6: 119.89084 | I6: =G6-1 -> -0.027287365 | L6: Variable | M6: Value | N6: Unit | O6: Notes
A7: =A6+1 -> 1974 | B7: ='MER Quantity Data'!B38 -> 56.294408 | C7: =VLOOKUP($A7,INDIRECT(C$1),MATCH(C$2,INDIRECT(C$1&"_col"),),) -> 4561.017 | D7: =IF(ISERROR(C7/B7),"",C7/B7) -> 81.020783 | F7: 10 Year: | G7: =G6^10-1 -> -0.24169212 | L7: SCC in $2020 | M7: 185 | N7: dollars/ton of CO2 | O7: Source: Rennert et al 2022 (full citation in paper)
A8: =A7+1 -> 1975 | B8: ='MER Quantity Data'!B39 -> 54.696919 | C8: =VLOOKUP($A8,INDIRECT(C$1),MATCH(C$2,INDIRECT(C$1&"_col"),),) -> 4427.937 | D8: =IF(ISERROR(C8/B8),"",C8/B8) -> 80.954048 | L8: 2020 Deflator | M8: ='MER GDP Data'!O89 -> 0 | N8: $2020/$2012
A9: =A8+1 -> 1976 | B9: ='MER Quantity Data'!B40 -> 54.683564 | C9: =VLOOKUP($A9,INDIRECT(C$1),MATCH(C$2,INDIRECT(C$1&"_col"),),) -> 4694.612 | D9: =IF(ISERROR(C9/B9),"",C9/B9) -> 85.850513 | L9: SCC in $2012 | M9: =M7/M8 -> #DIV/0! | N9: dollars/ton of CO2
A10: =A9+1 -> 1977 | B10: ='MER Quantity Data'!B41 -> 55.059451 | C10: =VLOOKUP($A10,INDIRECT(C$1),MATCH(C$2,INDIRECT(C$1&"_col"),),) -> 4835.148 | D10: =IF(ISERROR(C10/B10),"",C10/B10) -> 87.816858 | L10: Emissions in 2020 | M10: ='MER Environment Data'!W65*1000000 -> 0 | N10: tons
A11: =A10+1 -> 1978 | B11: ='MER Quantity Data'!B42 -> 55.03064 | C11: =VLOOKUP($A11,INDIRECT(C$1),MATCH(C$2,INDIRECT(C$1&"_col"),),) -> 4884.113 | D11: =IF(ISERROR(C11/B11),"",C11/B11) -> 88.752611 | L11: Damage in 2020 | M11: =M10*M9 -> #DIV/0! | N11: dollars
A12: =A11+1 -> 1979 | B12: ='MER Quantity Data'!B43 -> 57.951852 | C12: =VLOOKUP($A12,INDIRECT(C$1),MATCH(C$2,INDIRECT(C$1&"_col"),),) -> 4949.897 | D12: =IF(ISERROR(C12/B12),"",C12/B12) -> 85.413957 | L12: Y in 2020 | M12: ='MER GDP Data'!N89*1000000000 -> 0 | N12: dollars
A13: =A12+1 -> 1980 | B13: ='MER Quantity Data'!B44 -> 58.979084 | C13: =VLOOKUP($A13,INDIRECT(C$1),MATCH(C$2,INDIRECT(C$1&"_col"),),) -> 4756.328 | D13: =IF(ISERROR(C13/B13),"",C13/B13) -> 80.644318 | L13: Fraction of Y Lost | M13: =M11/M12 -> #DIV/0!
A14: =A13+1 -> 1981 | B14: ='MER Quantity Data'!B45 -> 58.488231 | C14: =VLOOKUP($A14,INDIRECT(C$1),MATCH(C$2,INDIRECT(C$1&"_col"),),) -> 4636.684 | D14: =IF(ISERROR(C14/B14),"",C14/B14) -> 79.275504
A15: =A14+1 -> 1982 | B15: ='MER Quantity Data'!B46 -> 57.415947 | C15: =VLOOKUP($A15,INDIRECT(C$1),MATCH(C$2,INDIRECT(C$1&"_col"),),) -> 4404.478 | D15: =IF(ISERROR(C15/B15),"",C15/B15) -> 76.711754
A16: =A15+1 -> 1983 | B16: ='MER Quantity Data'!B47 -> 54.368171 | C16: =VLOOKUP($A16,INDIRECT(C$1),MATCH(C$2,INDIRECT(C$1&"_col"),),) -> 4383.992 | D16: =IF(ISERROR(C16/B16),"",C16/B16) -> 80.635267
A17: =A16+1 -> 1984 | B17: ='MER Quantity Data'!B48 -> 58.809192 | C17: =VLOOKUP($A17,INDIRECT(C$1),MATCH(C$2,INDIRECT(C$1&"_col"),),) -> 4612.908 | D17: =IF(ISERROR(C17/B17),"",C17/B17) -> 78.438554
A18: =A17+1 -> 1985 | B18: ='MER Quantity Data'!B49 -> 57.501721 | C18: =VLOOKUP($A18,INDIRECT(C$1),MATCH(C$2,INDIRECT(C$1&"_col"),),) -> 4605.41 | D18: =IF(ISERROR(C18/B18),"",C18/B18) -> 80.09169
A19: =A18+1 -> 1986 | B19: ='MER Quantity Data'!B50 -> 56.539007 | C19: =VLOOKUP($A19,INDIRECT(C$1),MATCH(C$2,INDIRECT(C$1&"_col"),),) -> 4615.724 | D19: =IF(ISERROR(C19/B19),"",C19/B19) -> 81.637868
A20: =A19+1 -> 1987 | B20: ='MER Quantity Data'!B51 -> 57.130643 | C20: =VLOOKUP($A20,INDIRECT(C$1),MATCH(C$2,INDIRECT(C$1&"_col"),),) -> 4775.616 | D20: =IF(ISERROR(C20/B20),"",C20/B20) -> 83.591147
A21: =A20+1 -> 1988 | B21: ='MER Quantity Data'!B52 -> 57.845857 | C21: =VLOOKUP($A21,INDIRECT(C$1),MATCH(C$2,INDIRECT(C$1&"_col"),),) -> 4998.283 | D21: =IF(ISERROR(C21/B21),"",C21/B21) -> 86.406931
A22: =A21+1 -> 1989 | B22: ='MER Quantity Data'!B53 -> 57.447703 | C22: =VLOOKUP($A22,INDIRECT(C$1),MATCH(C$2,INDIRECT(C$1&"_col"),),) -> 5084.633 | D22: =IF(ISERROR(C22/B22),"",C22/B22) -> 88.5089
A23: =A22+1 -> 1990 | B23: ='MER Quantity Data'!B54 -> 58.523186 | C23: =VLOOKUP($A23,INDIRECT(C$1),MATCH(C$2,INDIRECT(C$1&"_col"),),) -> 5037.975 | D23: =IF(ISERROR(C23/B23),"",C23/B23) -> 86.085112
A24: =A23+1 -> 1991 | B24: ='MER Quantity Data'!B55 -> 57.831148 | C24: =VLOOKUP($A24,INDIRECT(C$1),MATCH(C$2,INDIRECT(C$1&"_col"),),) -> 4990.804 | D24: =IF(ISERROR(C24/B24),"",C24/B24) -> 86.299584
A25: =A24+1 -> 1992 | B25: ='MER Quantity Data'!B56 -> 57.614681 | C25: =VLOOKUP($A25,INDIRECT(C$1),MATCH(C$2,INDIRECT(C$1&"_col"),),) -> 5088.755 | D25: =IF(ISERROR(C25/B25),"",C25/B25) -> 88.323929
... A54: =A53+1 -> 2021 | B54: ='MER Quantity Data'!B85 -> 77.891227 | C54: =VLOOKUP($A54,INDIRECT(C$1),MATCH(C$2,INDIRECT(C$1&"_col"),),) -> 4903.572 | D54: =IF(ISERROR(C54/B54),"",C54/B54) -> 62.954099

Sheet EIA SEDS Codes
B2: State Energy Data System
B3: Data Series Names (MSN) and Descriptions
B6: The MSNs are five-character codes, most of which are structured as follows:
B7: First and second characters - describes an energy source (for example, NG for natural gas, MG for motor gasoline)
B8: Third and fourth characters - describes an energy sector or an energy activity (for example, RC for residential consumption, PR for production)
B9: Fifth character - describes a type of data (for example, P for data in physical unit, B for data in billion Btu)
B11: MSN | C11: Description | D11: Unit
B12: ABICB | C12: Aviation gasoline blending components consumed by the industrial sector | D12: Billion Btu
B13: ABICP | C13: Aviation gasoline blending components consumed by the industrial sector | D13: Thousand barrels
B14: ARICB | C14: Asphalt and road oil consumed by the industrial sector | D14: Billion Btu
B15: ARICD | C15: Asphalt and road oil price in the industrial sector | D15: Dollars per million Btu
B16: ARICP | C16: Asphalt and road oil consumed by the industrial sector | D16: Thousand barrels
B17: ARICV | C17: Asphalt and road oil expenditures in the industrial sector | D17: Million dollars
B18: ARTCB | C18: Asphalt and road oil total consumption | D18: Billion Btu
B19: ARTCD | C19: Asphalt and road oil average price, all sectors | D19: Dollars per million Btu
B20: ARTCP | C20: Asphalt and road oil total consumption | D20: Thousand barrels
B21: ARTCV | C21: Asphalt and road oil total expenditures | D21: Million dollars
B22: ARTXB | C22: Asphalt and road oil total end-use consumption | D22: Billion Btu
... B770: ZWHDP | C770: Heating degree days (HDD) | D770: Days

Sheet SEDS Quantities
A1: Data_Status | B1: State | C1: MSN | D1: 1960 | E1: 1961 | F1: 1962 | G1: 1963 | H1: 1964 | I1: 1965 | J1: 1966 | K1: 1967 | L1: 1968 | M1: 1969 | N1: 1970 | O1: 1971 | P1: 1972 | Q1: 1973 | R1: 1974 | S1: 1975 | T1: 1976 | U1: 1977 | V1: 1978 | W1: 1979 | X1: 1980 | Y1: 1981 | Z1: 1982 | AA1: 1983 | AB1: 1984 | AC1: 1985 | AD1: 1986 | AE1: 1987 | AF1: 1988 | AG1: 1989 | AH1: 1990 | AI1: 1991 | AJ1: 1992 | AK1: 1993 | AL1: 1994 | AM1: 1995 | AN1: 1996 | AO1: 1997 | AP1: 1998 | AQ1: 1999 | AR1: 2000 | AS1: 2001 | AT1: 2002 | AU1: 2003 | AV1: 2004 | AW1: 2005 | AX1: 2006 | AY1: 2007 | AZ1: 2008 | BA1: 2009 | BB1: 2010 | BC1: 2011 | BD1: 2012 | BE1: 2013 | BF1: 2014 | BG1: 2015 | BH1: 2016 | BI1: 2017 | BJ1: 2018 | BK1: 2019 | BL1: 2020 | BM1: 2021
A2: 2021F | B2: US | C2: ABICB | D2: 0 | E2: 0 | F2: 0 | G2: 0 | H2: 0 | I2: 0 | J2: 0 | K2: 0 | L2: 0 | M2: 0 | N2: 0 | O2: 0 | P2: 0 | Q2: 0 | R2: 0 | S2: 0 | T2: 0 | U2: 0 | V2: 0 | W2: 0 | X2: 0 | Y2: 5169 | Z2: 4937 | AA2: 712 | AB2: 86 | AC2: 3867 | AD2: 545 | AE2: 45 | AF2: -1070 | AG2: 106 | AH2: 237 | AI2: -81 | AJ2: 156 | AK2: 146 | AL2: 6098 | AM2: 5290 | AN2: 6951 | AO2: 9056 | AP2: 4003 | AQ2: 6396 | AR2: 3816 | AS2: 6073 | AT2: 7516 | AU2: 7471 | AV2: 10616 | AW2: 8324 | AX2: 641 | AY2: 1782 | AZ2: 96 | BA2: -793 | BB2: -242 | BC2: 10 | BD2: -5 | BE2: -379 | BF2: -141 | BG2: -348 | BH2: -293 | BI2: -192 | BJ2: -1555 | BK2: -1191 | BL2: -787 | BM2: -833
A3: 2021F | B3: US | C3: ABICP | D3: 0 | E3: 0 | F3: 0 | G3: 0 | H3: 0 | I3: 0 | J3: 0 | K3: 0 | L3: 0 | M3: 0 | N3: 0 | O3: 0 | P3: 0 | Q3: 0 | R3: 0 | S3: 0 | T3: 0 | U3: 0 | V3: 0 | W3: 0 | X3: 0 | Y3: 1024 | Z3: 978 | AA3: 141 | AB3: 17 | AC3: 766 | AD3: 108 | AE3: 9 | AF3: -212 | AG3: 21 | AH3: 47 | AI3: -16 | AJ3: 31 | AK3: 29 | AL3: 1208 | AM3: 1048 | AN3: 1377 | AO3: 1794 | AP3: 793 | AQ3: 1267 | AR3: 756 | AS3: 1203 | AT3: 1489 | AU3: 1480 | AV3: 2103 | AW3: 1649 | AX3: 127 | AY3: 353 | AZ3: 19 | BA3: -157 | BB3: -48 | BC3: 2 | BD3: -1 | BE3: -75 | BF3: -28 | BG3: -69 | BH3: -58 | BI3: -38 | BJ3: -308 | BK3: -236 | BL3: -156 | BM3: -165
A4: 2021F | B4: US | C4: ARICB | D4: 733782 | E4: 753551 | F4: 803533 | G4: 824642 | H4: 840781 | I4: 890266 | J4: 935557 | K4: 917215 | L4: 983661 | M4: 1008977 | N4: 1082451 | O4: 1108298 | P4: 1136919 | Q4: 1263720 | R4: 1165375 | S4: 1014226 | T4: 998121 | U4: 1056365 | V4: 1159621 | W4: 1153032 | X4: 962207 | Y4: 827788 | Z4: 829407 | AA4: 904095 | AB4: 992095 | AC4: 1029482 | AD4: 1085736 | AE4: 1130011 | AF4: 1136322 | AG4: 1096028 | AH4: 1170192 | AI4: 1076538 | AJ4: 1102220 | AK4: 1149017 | AL4: 1172920 | AM4: 1178175 | AN4: 1175932 | AO4: 1223566 | AP4: 1262552 | AQ4: 1324413 | AR4: 1275678 | AS4: 1256865 | AT4: 1239950 | AU4: 1219538 | AV4: 1303848 | AW4: 1323238 | AX4: 1261165 | AY4: 1197041 | AZ4: 1011970 | BA4: 873085 | BB4: 877770 | BC4: 859488 | BD4: 826700 | BE4: 783347 | BF4: 792637 | BG4: 831663 | BH4: 853363 | BI4: 849182 | BJ4: 792763 | BK4: 843880 | BL4: 832274 | BM4: 898083
A5: 2021F | B5: US | C5: ARICP | D5: 110576 | E5: 113555 | F5: 121087 | G5: 124268 | H5: 126700 | I5: 134157 | J5: 140982 | K5: 138218 | L5: 148231 | M5: 152046 | N5: 163118 | O5: 167013 | P5: 171326 | Q5: 190434 | R5: 175614 | S5: 152837 | T5: 150410 | U5: 159187 | V5: 174747 | W5: 173754 | X5: 144998 | Y5: 124742 | Z5: 124986 | AA5: 136241 | AB5: 149502 | AC5: 155136 | AD5: 163613 | AE5: 170285 | AF5: 171236 | AG5: 165164 | AH5: 176340 | AI5: 162227 | AJ5: 166097 | AK5: 173149 | AL5: 176751 | AM5: 177543 | AN5: 177205 | AO5: 184383 | AP5: 190258 | AQ5: 199580 | AR5: 192236 | AS5: 189401 | AT5: 186852 | AU5: 183776 | AV5: 196481 | AW5: 199403 | AX5: 190049 | AY5: 180386 | AZ5: 152497 | BA5: 131568 | BB5: 132274 | BC5: 129519 | BD5: 124578 | BE5: 118045 | BF5: 119445 | BG5: 125326 | BH5: 128596 | BI5: 127966 | BJ5: 119464 | BK5: 127167 | BL5: 125418 | BM5: 135335
A6: 2021F | B6: US | C6: ARTCB | D6: 733782 | E6: 753551 | F6: 803533 | G6: 824642 | H6: 840781 | I6: 890266 | J6: 935557 | K6: 917215 | L6: 983661 | M6: 1008977 | N6: 1082451 | O6: 1108298 | P6: 1136919 | Q6: 1263720 | R6: 1165375 | S6: 1014226 | T6: 998121 | U6: 1056365 | V6: 1159621 | W6: 1153032 | X6: 962207 | Y6: 827788 | Z6: 829407 | AA6: 904095 | AB6: 992095 | AC6: 1029482 | AD6: 1085736 | AE6: 1130011 | AF6: 1136322 | AG6: 1096028 | AH6: 1170192 | AI6: 1076538 | AJ6: 1102220 | AK6: 1149017 | AL6: 1172920 | AM6: 1178175 | AN6: 1175932 | AO6: 1223566 | AP6: 1262552 | AQ6: 1324413 | AR6: 1275678 | AS6: 1256865 | AT6: 1239950 | AU6: 1219538 | AV6: 1303848 | AW6: 1323238 | AX6: 1261165 | AY6: 1197041 | AZ6: 1011970 | BA6: 873085 | BB6: 877770 | BC6: 859488 | BD6: 826700 | BE6: 783347 | BF6: 792637 | BG6: 831663 | BH6: 853363 | BI6: 849182 | BJ6: 792763 | BK6: 843880 | BL6: 832274 | BM6: 898083
A7: 2021F | B7: US | C7: ARTCP | D7: 110576 | E7: 113555 | F7: 121087 | G7: 124268 | H7: 126700 | I7: 134157 | J7: 140982 | K7: 138218 | L7: 148231 | M7: 152046 | N7: 163118 | O7: 167013 | P7: 171326 | Q7: 190434 | R7: 175614 | S7: 152837 | T7: 150410 | U7: 159187 | V7: 174747 | W7: 173754 | X7: 144998 | Y7: 124742 | Z7: 124986 | AA7: 136241 | AB7: 149502 | AC7: 155136 | AD7: 163613 | AE7: 170285 | AF7: 171236 | AG7: 165164 | AH7: 176340 | AI7: 162227 | AJ7: 166097 | AK7: 173149 | AL7: 176751 | AM7: 177543 | AN7: 177205 | AO7: 184383 | AP7: 190258 | AQ7: 199580 | AR7: 192236 | AS7: 189401 | AT7: 186852 | AU7: 183776 | AV7: 196481 | AW7: 199403 | AX7: 190049 | AY7: 180386 | AZ7: 152497 | BA7: 131568 | BB7: 132274 | BC7: 129519 | BD7: 124578 | BE7: 118045 | BF7: 119445 | BG7: 125326 | BH7: 128596 | BI7: 127966 | BJ7: 119464 | BK7: 127167 | BL7: 125418 | BM7: 135335
A8: 2021F | B8: US | C8: ARTXB | D8: 733782 | E8: 753551 | F8: 803533 | G8: 824642 | H8: 840781 | I8: 890266 | J8: 935557 | K8: 917215 | L8: 983661 | M8: 1008977 | N8: 1082451 | O8: 1108298 | P8: 1136919 | Q8: 1263720 | R8: 1165375 | S8: 1014226 | T8: 998121 | U8: 1056365 | V8: 1159621 | W8: 1153032 | X8: 962207 | Y8: 827788 | Z8: 829407 | AA8: 904095 | AB8: 992095 | AC8: 1029482 | AD8: 1085736 | AE8: 1130011 | AF8: 1136322 | AG8: 1096028 | AH8: 1170192 | AI8: 1076538 | AJ8: 1102220 | AK8: 1149017 | AL8: 1172920 | AM8: 1178175 | AN8: 1175932 | AO8: 1223566 | AP8: 1262552 | AQ8: 1324413 | AR8: 1275678 | AS8: 1256865 | AT8: 1239950 | AU8: 1219538 | AV8: 1303848 | AW8: 1323238 | AX8: 1261165 | AY8: 1197041 | AZ8: 1011970 | BA8: 873085 | BB8: 877770 | BC8: 859488 | BD8: 826700 | BE8: 783347 | BF8: 792637 | BG8: 831663 | BH8: 853363 | BI8: 849182 | BJ8: 792763 | BK8: 843880 | BL8: 832274 | BM8: 898083
A9: 2021F | B9: US | C9: ARTXP | D9: 110576 | E9: 113555 | F9: 121087 | G9: 124268 | H9: 126700 | I9: 134157 | J9: 140982 | K9: 138218 | L9: 148231 | M9: 152046 | N9: 163118 | O9: 167013 | P9: 171326 | Q9: 190434 | R9: 175614 | S9: 152837 | T9: 150410 | U9: 159187 | V9: 174747 | W9: 173754 | X9: 144998 | Y9: 124742 | Z9: 124986 | AA9: 136241 | AB9: 149502 | AC9: 155136 | AD9: 163613 | AE9: 170285 | AF9: 171236 | AG9: 165164 | AH9: 176340 | AI9: 162227 | AJ9: 166097 | AK9: 173149 | AL9: 176751 | AM9: 177543 | AN9: 177205 | AO9: 184383 | AP9: 190258 | AQ9: 199580 | AR9: 192236 | AS9: 189401 | AT9: 186852 | AU9: 183776 | AV9: 196481 | AW9: 199403 | AX9: 190049 | AY9: 180386 | AZ9: 152497 | BA9: 131568 | BB9: 132274 | BC9: 129519 | BD9: 124578 | BE9: 118045 | BF9: 119445 | BG9: 125326 | BH9: 128596 | BI9: 127966 | BJ9: 119464 | BK9: 127167 | BL9: 125418 | BM9: 135335
A10: 2021F | B10: US | C10: AVACB | D10: 297903 | E10: 290396 | F10: 262915 | G10: 253193 | H10: 235025 | I10: 221592 | J10: 194091 | K10: 166099 | L10: 154590 | M10: 128981 | N10: 100470 | O10: 90319 | P10: 85437 | Q10: 83448 | R10: 81853 | S10: 71010 | T10: 67451 | U10: 70329 | V10: 71454 | W10: 70314 | X10: 64347 | Y10: 56270 | Z10: 46977 | AA10: 47673 | AB10: 43877 | AC10: 50324 | AD10: 58925 | AE10: 45639 | AF10: 48991 | AG10: 47587 | AH10: 44978 | AI10: 41722 | AJ10: 41055 | AK10: 38395 | AL10: 38138 | AM10: 39581 | AN10: 37355 | AO10: 39697 | AP10: 35498 | AQ10: 39172 | AR10: 36285 | AS10: 34937 | AT10: 33731 | AU10: 30222 | AV10: 31242 | AW10: 35366 | AX10: 33448 | AY10: 31590 | AZ10: 28284 | BA10: 26558 | BB10: 27047 | BC10: 27057 | BD10: 25114 | BE10: 22358 | BF10: 21696 | BG10: 21141 | BH10: 20465 | BI10: 20949 | BJ10: 22393 | BK10: 23387 | BL10: 20202 | BM10: 21550
A11: 2021F | B11: US | C11: AVACP | D11: 59014 | E11: 57527 | F11: 52083 | G11: 50157 | H11: 46558 | I11: 43897 | J11: 38449 | K11: 32904 | L11: 30624 | M11: 25551 | N11: 19903 | O11: 17892 | P11: 16925 | Q11: 16531 | R11: 16215 | S11: 14067 | T11: 13362 | U11: 13932 | V11: 14155 | W11: 13929 | X11: 12747 | Y11: 11147 | Z11: 9306 | AA11: 9444 | AB11: 8692 | AC11: 9969 | AD11: 11673 | AE11: 9041 | AF11: 9705 | AG11: 9427 | AH11: 8910 | AI11: 8265 | AJ11: 8133 | AK11: 7606 | AL11: 7555 | AM11: 7841 | AN11: 7400 | AO11: 7864 | AP11: 7032 | AQ11: 7760 | AR11: 7188 | AS11: 6921 | AT11: 6682 | AU11: 5987 | AV11: 6189 | AW11: 7006 | AX11: 6626 | AY11: 6258 | AZ11: 5603 | BA11: 5261 | BB11: 5358 | BC11: 5360 | BD11: 4975 | BE11: 4429 | BF11: 4298 | BG11: 4188 | BH11: 4054 | BI11: 4150 | BJ11: 4436 | BK11: 4633 | BL11: 4002 | BM11: 4269
A12: 2021F | B12: US | C12: AVTCB | D12: 297903 | E12: 290396 | F12: 262915 | G12: 253193 | H12: 235025 | I12: 221592 | J12: 194091 | K12: 166099 | L12: 154590 | M12: 128981 | N12: 100470 | O12: 90319 | P12: 85437 | Q12: 83448 | R12: 81853 | S12: 71010 | T12: 67451 | U12: 70329 | V12: 71454 | W12: 70314 | X12: 64347 | Y12: 56270 | Z12: 46977 | AA12: 47673 | AB12: 43877 | AC12: 50324 | AD12: 58925 | AE12: 45639 | AF12: 48991 | AG12: 47587 | AH12: 44978 | AI12: 41722 | AJ12: 41055 | AK12: 38395 | AL12: 38138 | AM12: 39581 | AN12: 37355 | AO12: 39697 | AP12: 35498 | AQ12: 39172 | AR12: 36285 | AS12: 34937 | AT12: 33731 | AU12: 30222 | AV12: 31242 | AW12: 35366 | AX12: 33448 | AY12: 31590 | AZ12: 28284 | BA12: 26558 | BB12: 27047 | BC12: 27057 | BD12: 25114 | BE12: 22358 | BF12: 21696 | BG12: 21141 | BH12: 20465 | BI12: 20949 | BJ12: 22393 | BK12: 23387 | BL12: 20202 | BM12: 21550
... A31: 2021F | B31: US | C31: BOTCP | D31: 0 | E31: 0 | F31: 0 | G31: 0 | H31: 0 | I31: 0 | J31: 0 | K31: 0 | L31: 0 | M31: 0 | N31: 0 | O31: 0 | P31: 0 | Q31: 0 | R31: 0 | S31: 0 | T31: 0 | U31: 0 | V31: 0 | W31: 0 | X31: 0 | Y31: 0 | Z31: 0 | AA31: 0 | AB31: 0 | AC31: 0 | AD31: 0 | AE31: 0 | AF31: 0 | AG31: 0 | AH31: 0 | AI31: 0 | AJ31: 0 | AK31: 0 | AL31: 0 | AM31: 0 | AN31: 0 | AO31: 0 | AP31: 0 | AQ31: 0 | AR31: 0 | AS31: 0 | AT31: 0 | AU31: 0 | AV31: 0 | AW31: 0 | AX31: 0 | AY31: 0 | AZ31: 0 | BA31: 0 | BB31: 0 | BC31: 0 | BD31: 0 | BE31: 0 | BF31: 288 | BG31: 396 | BH31: 464 | BI31: 585 | BJ31: 585 | BK31: 795 | BL31: 784 | BM31: 1885
A32: 2021F | B32: US | C32: BQICB | BB32: 164731 | BC32: 107136 | BD32: 122276 | BE32: 187558 | BF32: 186108 | BG32: 203877 | BH32: 133089 | BI32: 61003 | BJ32: 55331 | BK32: 80243 | BL32: -17072 | BM32: 36160
A33: 2021F | B33: US | C33: BQICP | BB33: 37843 | BC33: 24612 | BD33: 28090 | BE33: 43087 | BF33: 42754 | BG33: 46836 | BH33: 30574 | BI33: 14014 | BJ33: 12711 | BK33: 18434 | BL33: -3922 | BM33: 8307
A34: 2021F | B34: US | C34: BQTCB | BB34: 164731 | BC34: 107136 | BD34: 122276 | BE34: 187558 | BF34: 186108 | BG34: 203877 | BH34: 133089 | BI34: 61003 | BJ34: 55331 | BK34: 80243 | BL34: -17072 | BM34: 36160
A35: 2021F | B35: US | C35: BQTCP | BB35: 37843 | BC35: 24612 | BD35: 28090 | BE35: 43087 | BF35: 42754 | BG35: 46836 | BH35: 30574 | BI35: 14014 | BJ35: 12711 | BK35: 18434 | BL35: -3922 | BM35: 8307
A36: 2021F | B36: US | C36: BTGBP | AZ36: 0 | BA36: 0 | BB36: 28 | BC36: 68 | BD36: 142 | BE36: 146 | BF36: 156 | BG36: 292 | BH36: 559 | BI36: 665 | BJ36: 852 | BK36: 1015 | BL36: 1508 | BM36: 4747
A37: 2021F | B37: US | C37: BYICB | BB37: 6636 | BC37: 889 | BD37: 626 | BE37: -5563 | BF37: 2486 | BG37: -8610 | BH37: -3847 | BI37: 5257 | BJ37: 13547 | BK37: 26 | BL37: -5694 | BM37: -4460
A38: 2021F | B38: US | C38: BYICP | BB38: 1516 | BC38: 203 | BD38: 143 | BE38: -1271 | BF38: 568 | BG38: -1967 | BH38: -879 | BI38: 1201 | BJ38: 3095 | BK38: 6 | BL38: -1301 | BM38: -1019
A39: 2021F | B39: US | C39: BYTCB | BB39: 6636 | BC39: 889 | BD39: 626 | BE39: -5563 | BF39: 2486 | BG39: -8610 | BH39: -3847 | BI39: 5257 | BJ39: 13547 | BK39: 26 | BL39: -5694 | BM39: -4460
A40: 2021F | B40: US | C40: BYTCP | BB40: 1516 | BC40: 203 | BD40: 143 | BE40: -1271 | BF40: 568 | BG40: -1967 | BH40: -879 | BI40: 1201 | BJ40: 3095 | BK40: 6 | BL40: -1301 | BM40: -1019
A41: 2021F | B41: US | C41: CCEXB | D41: 8754 | E41: 11036 | F41: 9027 | G41: 11185 | H41: 12995 | I41: 20683 | J41: 27330 | K41: 17608 | L41: 19642 | M41: 40399 | N41: 61454 | O41: 37423 | P41: 30554 | Q41: 34596 | R41: 31694 | S41: 31570 | T41: 32612 | U41: 30777 | V41: 17186 | W41: 35712 | X41: 51362 | Y41: 29020 | Z41: 24632 | AA41: 16504 | AB41: 25911 | AC41: 27833 | AD41: 24909 | AE41: 14243 | AF41: 27112 | AG41: 26918 | AH41: 14189 | AI41: 19645 | AJ41: 17402 | AK41: 26333 | AL41: 24456 | AM41: 33678 | AN41: 40233 | AO41: 31405 | AP41: 27999 | AQ41: 22261 | AR41: 28414 | AS41: 33373 | AT41: 19637 | AU41: 17900 | AV41: 32701 | AW41: 43335 | AX41: 40089 | AY41: 35807 | AZ41: 48582 | BA41: 32409 | BB41: 36278 | BC41: 24058 | BD41: 24162 | BE41: 20833 | BF41: 23461 | BG41: 21251 | BH41: 24808 | BI41: 30048 | BJ41: 28549 | BK41: 23990 | BL41: 16949 | BM41: 51618
A42: 2021F | B42: US | C42: CCEXP | D42: 353 | E42: 445 | F42: 364 | G42: 451 | H42: 524 | I42: 834 | J42: 1102 | K42: 710 | L42: 792 | M42: 1629 | N42: 2478 | O42: 1509 | P42: 1232 | Q42: 1395 | R42: 1278 | S42: 1273 | T42: 1315 | U42: 1241 | V42: 693 | W42: 1440 | X42: 2071 | Y42: 1170 | Z42: 993 | AA42: 665 | AB42: 1045 | AC42: 1122 | AD42: 1004 | AE42: 574 | AF42: 1093 | AG42: 1085 | AH42: 572 | AI42: 792 | AJ42: 702 | AK42: 1062 | AL42: 986 | AM42: 1358 | AN42: 1622 | AO42: 1266 | AP42: 1129 | AQ42: 898 | AR42: 1146 | AS42: 1346 | AT42: 792 | AU42: 722 | AV42: 1319 | AW42: 1747 | AX42: 1616 | AY42: 1444 | AZ42: 1959 | BA42: 1307 | BB42: 1463 | BC42: 970 | BD42: 974 | BE42: 840 | BF42: 946 | BG42: 857 | BH42: 1000 | BI42: 1212 | BJ42: 1151 | BK42: 967 | BL42: 683 | BM42: 2081
A43: 2021F | B43: US | C43: CCIMB | D43: 3125 | E43: 3150 | F43: 3522 | G43: 3794 | H43: 2554 | I43: 2232 | J43: 2381 | K43: 2282 | L43: 2331 | M43: 4290 | N43: 3794 | O43: 4315 | P43: 4588 | Q43: 27131 | R43: 87792 | S43: 45111 | T43: 32513 | U43: 45359 | V43: 141906 | W43: 98555 | X43: 16332 | Y43: 13071 | Z43: 2976 | AA43: 868 | AB43: 14423 | AC43: 14341 | AD43: 8155 | AE43: 22873 | AF43: 66663 | AG43: 57322 | AH43: 18966 | AI43: 29334 | AJ43: 52027 | AK43: 53442 | AL43: 82785 | AM43: 94739 | AN43: 63044 | AO43: 77844 | AP43: 95094 | AQ43: 79953 | AR43: 93777 | AS43: 62633 | AT43: 80395 | AU43: 68415 | AV43: 170463 | AW43: 87526 | AX43: 100876 | AY43: 60998 | AZ43: 89354 | BA43: 8598 | BB43: 30107 | BC43: 35162 | BD43: 28146 | BE43: 3411 | BF43: 1901 | BG43: 3470 | BH43: 5669 | BI43: 1450 | BJ43: 2895 | BK43: 2868 | BL43: 4010 | BM43: 2904
A44: 2021F | B44: US | C44: CCIMP | D44: 126 | E44: 127 | F44: 142 | G44: 153 | H44: 103 | I44: 90 | J44: 96 | K44: 92 | L44: 94 | M44: 173 | N44: 153 | O44: 174 | P44: 185 | Q44: 1094 | R44: 3540 | S44: 1819 | T44: 1311 | U44: 1829 | V44: 5722 | W44: 3974 | X44: 659 | Y44: 527 | Z44: 120 | AA44: 35 | AB44: 582 | AC44: 578 | AD44: 329 | AE44: 922 | AF44: 2688 | AG44: 2311 | AH44: 765 | AI44: 1183 | AJ44: 2098 | AK44: 2155 | AL44: 3338 | AM44: 3820 | AN44: 2542 | AO44: 3139 | AP44: 3834 | AQ44: 3224 | AR44: 3781 | AS44: 2526 | AT44: 3242 | AU44: 2759 | AV44: 6873 | AW44: 3529 | AX44: 4068 | AY44: 2460 | AZ44: 3603 | BA44: 347 | BB44: 1214 | BC44: 1418 | BD44: 1135 | BE44: 138 | BF44: 77 | BG44: 140 | BH44: 229 | BI44: 58 | BJ44: 117 | BK44: 116 | BL44: 162 | BM44: 117
A45: 2021F | B45: US | C45: CCNIB | D45: -5630 | E45: -7886 | F45: -5506 | G45: -7390 | H45: -10441 | I45: -18451 | J45: -24949 | K45: -15326 | L45: -17310 | M45: -36109 | N45: -57660 | O45: -33108 | P45: -25966 | Q45: -7465 | R45: 56098 | S45: 13541 | T45: -99 | U45: 14582 | V45: 124719 | W45: 62843 | X45: -35030 | Y45: -15949 | Z45: -21656 | AA45: -15636 | AB45: -11488 | AC45: -13492 | AD45: -16754 | AE45: 8630 | AF45: 39551 | AG45: 30404 | AH45: 4778 | AI45: 9688 | AJ45: 34625 | AK45: 27110 | AL45: 58329 | AM45: 61061 | AN45: 22811 | AO45: 46440 | AP45: 67095 | AQ45: 57692 | AR45: 65363 | AS45: 29260 | AT45: 60758 | AU45: 50515 | AV45: 137762 | AW45: 44191 | AX45: 60787 | AY45: 25191 | AZ45: 40772 | BA45: -23811 | BB45: -6171 | BC45: 11104 | BD45: 3983 | BE45: -17422 | BF45: -21560 | BG45: -17781 | BH45: -19139 | BI45: -28598 | BJ45: -25654 | BK45: -21122 | BL45: -12939 | BM45: -48713
A46: 2021F | B46: US | C46: CCNIP | D46: -227 | E46: -318 | F46: -222 | G46: -298 | H46: -421 | I46: -744 | J46: -1006 | K46: -618 | L46: -698 | M46: -1456 | N46: -2325 | O46: -1335 | P46: -1047 | Q46: -301 | R46: 2262 | S46: 546 | T46: -4 | U46: 588 | V46: 5029 | W46: 2534 | X46: -1413 | Y46: -643 | Z46: -873 | AA46: -630 | AB46: -463 | AC46: -544 | AD46: -676 | AE46: 348 | AF46: 1595 | AG46: 1226 | AH46: 193 | AI46: 391 | AJ46: 1396 | AK46: 1093 | AL46: 2352 | AM46: 2462 | AN46: 920 | AO46: 1873 | AP46: 2705 | AQ46: 2326 | AR46: 2636 | AS46: 1180 | AT46: 2450 | AU46: 2037 | AV46: 5555 | AW46: 1782 | AX46: 2451 | AY46: 1016 | AZ46: 1644 | BA46: -960 | BB46: -249 | BC46: 448 | BD46: 161 | BE46: -703 | BF46: -869 | BG46: -717 | BH46: -772 | BI46: -1153 | BJ46: -1034 | BK46: -852 | BL46: -522 | BM46: -1964
A47: 2021F | B47: US | C47: CLACB | D47: 75624 | E47: 19096 | F47: 17032 | G47: 16593 | H47: 17586 | I47: 16135 | J47: 14898 | K47: 11351 | L47: 10139 | M47: 7502 | N47: 6917 | O47: 4738 | P47: 3705 | Q47: 2633 | R47: 1801 | S47: 542 | T47: 273 | U47: 204 | V47: 0 | W47: 0 | X47: 0 | Y47: 0 | Z47: 0 | AA47: 0 | AB47: 0 | AC47: 0 | AD47: 0 | AE47: 0 | AF47: 0 | AG47: 0 | AH47: 0 | AI47: 0 | AJ47: 0 | AK47: 0 | AL47: 0 | AM47: 0 | AN47: 0 | AO47: 0 | AP47: 0 | AQ47: 0 | AR47: 0 | AS47: 0 | AT47: 0 | AU47: 0 | AV47: 0 | AW47: 0 | AX47: 0 | AY47: 0 | AZ47: 0 | BA47: 0 | BB47: 0 | BC47: 0 | BD47: 0 | BE47: 0 | BF47: 0 | BG47: 0 | BH47: 0 | BI47: 0 | BJ47: 0 | BK47: 0 | BL47: 0 | BM47: 0
A48: 2021F | B48: US | C48: CLACK | D48: 24.604 | E48: 24.569 | F48: 24.558 | G48: 24.524 | H48: 24.49 | I48: 24.387 | J48: 24.227 | K48: 24.056 | L48: 24.034 | M48: 23.737 | N48: 22.973 | O48: 22.653 | P48: 22.539 | Q48: 22.585 | R48: 22.42 | S48: 22.439 | T48: 22.528 | U48: 22.29 | V48: 22.175 | W48: 22.436 | X48: 22.69 | Y48: 22.572 | Z48: 22.695 | AA48: 22.68 | AB48: 22.525 | AC48: 22.013 | AD48: 22.185 | AE48: 22.36 | AF48: 22.341 | AG48: 22.324 | AH48: 22.444 | AI48: 22.448 | AJ48: 22.242 | AK48: 22.111 | AL48: 22.046 | AM48: 21.931 | AN48: 22.087 | AO48: 22.157 | AP48: 22.093 | AQ48: 22.093 | AR48: 0 | AS48: 0 | AT48: 0 | AU48: 0 | AV48: 0 | AW48: 0 | AX48: 0 | AY48: 0 | AZ48: 0 | BA48: 0 | BB48: 0 | BC48: 0 | BD48: 0 | BE48: 0 | BF48: 0 | BG48: 0 | BH48: 0 | BI48: 0 | BJ48: 0 | BK48: 0 | BL48: 0 | BM48: 0
A49: 2021F | B49: US | C49: CLACP | D49: 3046 | E49: 770 | F49: 687 | G49: 670 | H49: 711 | I49: 655 | J49: 609 | K49: 467 | L49: 417 | M49: 313 | N49: 298 | O49: 207 | P49: 163 | Q49: 116 | R49: 80 | S49: 24 | T49: 12 | U49: 9 | V49: 0 | W49: 0 | X49: 0 | Y49: 0 | Z49: 0 | AA49: 0 | AB49: 0 | AC49: 0 | AD49: 0 | AE49: 0 | AF49: 0 | AG49: 0 | AH49: 0 | AI49: 0 | AJ49: 0 | AK49: 0 | AL49: 0 | AM49: 0 | AN49: 0 | AO49: 0 | AP49: 0 | AQ49: 0 | AR49: 0 | AS49: 0 | AT49: 0 | AU49: 0 | AV49: 0 | AW49: 0 | AX49: 0 | AY49: 0 | AZ49: 0 | BA49: 0 | BB49: 0 | BC49: 0 | BD49: 0 | BE49: 0 | BF49: 0 | BG49: 0 | BH49: 0 | BI49: 0 | BJ49: 0 | BK49: 0 | BL49: 0 | BM49: 0
A50: 2021F | B50: US | C50: CLCCB | D50: 401969 | E50: 366139 | F50: 357649 | G50: 314331 | H50: 271710 | I50: 262503 | J50: 260256 | K50: 223054 | L50: 205459 | M50: 192705 | N50: 163002 | O50: 177549 | P50: 152546 | Q50: 159585 | R50: 173737 | S50: 145705 | T50: 144001 | U50: 147778 | V50: 164620 | W50: 150807 | X50: 116684 | Y50: 137034 | Z50: 155495 | AA50: 161912 | AB50: 169172 | AC50: 137630 | AD50: 135642 | AE50: 127108 | AF50: 131184 | AG50: 115299 | AH50: 123829 | AI50: 115432 | AJ50: 116757 | AK50: 116507 | AL50: 117116 | AM50: 116329 | AN50: 120065 | AO50: 128728 | AP50: 100594 | AQ50: 101615 | AR50: 85811 | AS50: 88293 | AT50: 87814 | AU50: 82868 | AV50: 102859 | AW50: 95743 | AX50: 64346 | AY50: 70384 | AZ50: 80427 | BA50: 73249 | BB50: 69590 | BC50: 61732 | BD50: 43654 | BE50: 41479 | BF50: 40461 | BG50: 31071 | BH50: 24027 | BI50: 20807 | BJ50: 18772 | BK50: 16714 | BL50: 14481 | BM50: 14645
A51: 2021F | B51: US | C51: CLCCP | D51: 16789 | E51: 15293 | F51: 14972 | G51: 13211 | H51: 11409 | I51: 11041 | J51: 11002 | K51: 9518 | L51: 8793 | M51: 8305 | N51: 7090 | O51: 7753 | P51: 6674 | Q51: 7004 | R51: 7764 | S51: 6587 | T51: 6330 | U51: 6447 | V51: 7323 | W51: 6710 | X51: 5097 | Y51: 6085 | Z51: 6839 | AA51: 7096 | AB51: 7395 | AC51: 6068 | AD51: 5904 | AE51: 5324 | AF51: 5561 | AG51: 4872 | AH51: 5379 | AI51: 4997 | AJ51: 5045 | AK51: 5101 | AL51: 5111 | AM51: 5052 | AN51: 5285 | AO51: 5752 | AP51: 4322 | AQ51: 4293 | AR51: 3673 | AS51: 3888 | AT51: 3912 | AU51: 3685 | AV51: 4610 | AW51: 4342 | AX51: 2936 | AY51: 3173 | AZ51: 3506 | BA51: 3210 | BB51: 3081 | BC51: 2793 | BD51: 2045 | BE51: 1951 | BF51: 1887 | BG51: 1503 | BH51: 1183 | BI51: 1061 | BJ51: 972 | BK51: 876 | BL51: 793 | BM51: 811
A52: 2021F | B52: US | C52: CLEIB | D52: 4226595 | E52: 4355064 | F52: 4622438 | G52: 5050061 | H52: 5379761 | I52: 5821355 | J52: 6301552 | K52: 6444876 | L52: 6993577 | M52: 7219168 | N52: 7228006 | O52: 7299249 | P52: 7842523 | Q52: 8659920 | R52: 8538706 | S52: 8789280 | T52: 9730659 | U52: 10258749 | V52: 10253442 | W52: 11270255 | X52: 12157926 | Y52: 12622872 | Z52: 12537754 | AA52: 13184982 | AB52: 13961625 | AC52: 14586431 | AD52: 14418435 | AE52: 15114830 | AF52: 15886154 | AG52: 16135278 | AH52: 16258995 | AI52: 16247935 | AJ52: 16463621 | AK52: 17194422 | AL52: 17259079 | AM52: 17465065 | AN52: 18427577 | AO52: 18902863 | AP52: 19215808 | AQ52: 19279063 | AR52: 20219797 | AS52: 19613575 | AT52: 19782944 | AU52: 20183337 | AV52: 20303713 | AW52: 20735427 | AX52: 20459989 | AY52: 20805249 | AZ52: 20510599 | BA52: 18223766 | BB52: 19133366 | BC52: 18035415 | BD52: 15821257 | BE52: 16450431 | BF52: 16427232 | BG52: 14138235 | BH52: 12996648 | BI52: 12622220 | BJ52: 12053020 | BK52: 10181470 | BL52: 8229142 | BM52: 9496416
... A54: 2021F | B54: US | C54: CLEIP | D54: 176685 | E54: 182185 | F54: 193316 | G54: 211332 | H54: 225425 | I54: 244788 | J54: 266477 | K54: 274185 | L54: 297779 | M54: 310641 | N54: 320182 | O54: 327301 | P54: 351768 | Q54: 389212 | R54: 391811 | S54: 405962 | T54: 448371 | U54: 477126 | V54: 481235 | W54: 527051 | X54: 569274 | Y54: 596797 | Z54: 593666 | AA54: 625211 | AB54: 664399 | AC54: 693841 | AD54: 685056 | AE54: 717894 | AF54: 758372 | AG54: 772190 | AH54: 782567 | AI54: 783874 | AJ54: 795094 | AK54: 831645 | AL54: 838354 | AM54: 850230 | AN54: 896921 | AO54: 921364 | AP54: 936619 | AQ54: 940922 | AR54: 985821 | AS54: 964433 | AT54: 977507 | AU54: 1005063 | AV54: 1016208 | AW54: 1037419 | AX54: 1026571 | AY54: 1045056 | AZ54: 1040483 | BA54: 933539 | BB54: 975052 | BC54: 932484 | BD54: 823551 | BE54: 857962 | BF54: 851602 | BG54: 738444 | BH54: 678554 | BI54: 664993 | BJ54: 637217 | BK54: 538606 | BL54: 435827 | BM54: 501366
A55: 2021F | B55: US | C55: CLGBP | AZ55: 313322 | BA55: 314294 | BB55: 317339 | BC55: 317640 | BD55: 309680 | BE55: 303306 | BF55: 299094 | BG55: 279720 | BH55: 266620 | BI55: 256547 | BJ55: 242786 | BK55: 228657 | BL55: 215554 | BM55: 209826
A56: 2021F | B56: US | C56: CLHCK | D56: 23.943 | E56: 23.942 | F56: 23.889 | G56: 23.794 | H56: 23.815 | I56: 23.776 | J56: 23.654 | K56: 23.436 | L56: 23.368 | M56: 23.205 | N56: 22.99 | O56: 22.902 | P56: 22.858 | Q56: 22.786 | R56: 22.378 | S56: 22.12 | T56: 22.748 | U56: 22.922 | V56: 22.478 | W56: 22.474 | X56: 22.892 | Y56: 22.519 | Z56: 22.736 | AA56: 22.817 | AB56: 22.876 | AC56: 22.682 | AD56: 22.975 | AE56: 23.875 | AF56: 23.588 | AG56: 23.665 | AH56: 23.021 | AI56: 23.099 | AJ56: 23.142 | AK56: 22.838 | AL56: 22.916 | AM56: 23.027 | AN56: 22.718 | AO56: 22.379 | AP56: 23.276 | AQ56: 23.668 | AR56: 23.364 | AS56: 22.706 | AT56: 22.449 | AU56: 22.488 | AV56: 22.314 | AW56: 22.053 | AX56: 21.915 | AY56: 22.179 | AZ56: 22.941 | BA56: 22.82 | BB56: 22.59 | BC56: 22.105 | BD56: 21.35 | BE56: 21.259 | BF56: 21.442 | BG56: 20.667 | BH56: 20.316 | BI56: 19.608 | BJ56: 19.321 | BK56: 19.082 | BL56: 18.258 | BM56: 18.067
A57: 2021F | B57: US | C57: CLICB | D57: 4547884 | E57: 4350831 | F57: 4392800 | G57: 4599452 | H57: 4923268 | I57: 5134435 | J57: 5223593 | K57: 4942087 | L57: 4866866 | M57: 4718533 | N57: 4663514 | O57: 3951081 | P57: 3995678 | Q57: 4044258 | R57: 3855006 | S57: 3657641 | T57: 3642139 | U57: 3442911 | V57: 3302449 | W57: 3582888 | X57: 3155354 | Y57: 3147737 | Z57: 2543952 | AA57: 2489325 | AB57: 2843097 | AC57: 2777190 | AD57: 2646289 | AE57: 2669971 | AF57: 2831324 | AG57: 2773940 | AH57: 2753900 | AI57: 2600434 | AJ57: 2511793 | AK57: 2499623 | AL57: 2506697 | AM57: 2500067 | AN57: 2438143 | AO57: 2396101 | AP57: 2254489 | AQ57: 2187568 | AR57: 2259324 | AS57: 2193574 | AT57: 2020119 | AU57: 2044047 | AV57: 2046302 | AW57: 1953954 | AX57: 1913516 | AY57: 1864461 | AZ57: 1791789 | BA57: 1394326 | BB57: 1625426 | BC57: 1566710 | BD57: 1516013 | BE57: 1546861 | BF57: 1528884 | BG57: 1379678 | BH57: 1206462 | BI57: 1196605 | BJ57: 1178166 | BK57: 1116741 | BL57: 939074 | BM57: 1036702
A58: 2021F | B58: US | C58: CLICP | D58: 177402 | E58: 170098 | F58: 171741 | G58: 180024 | H58: 192369 | I58: 200846 | J58: 205076 | K58: 194645 | L58: 191648 | M58: 186586 | N58: 186637 | O58: 158866 | P58: 160624 | Q58: 162139 | R58: 155094 | S58: 147244 | T58: 146491 | U58: 139202 | V58: 134479 | W58: 145085 | X58: 127003 | Y58: 128410 | Z58: 105004 | AA58: 103013 | AB58: 117767 | AC58: 116429 | AD58: 111446 | AE58: 112052 | AF58: 118140 | AG58: 116643 | AH58: 115207 | AI58: 109259 | AJ58: 106408 | AK58: 106215 | AL58: 106919 | AM58: 106067 | AN58: 103395 | AO58: 101718 | AP58: 95628 | AQ58: 92846 | AR58: 94147 | AS58: 91344 | AT58: 84403 | AU58: 85509 | AV58: 85865 | AW58: 83774 | AX58: 82429 | AY58: 79331 | AZ58: 76463 | BA58: 60641 | BB58: 70381 | BC58: 67671 | BD58: 63589 | BE58: 64529 | BF58: 64243 | BG58: 58167 | BH58: 51333 | BI58: 50801 | BJ58: 49917 | BK58: 47062 | BL58: 40073 | BM58: 43434
A59: 2021F | B59: US | C59: CLKCB | D59: 2180349 | E59: 1987969 | F59: 2000581 | G59: 2091438 | H59: 2390576 | I59: 2552406 | J59: 2582365 | K59: 2485301 | L59: 2444894 | M59: 2502344 | N59: 2584122 | O59: 2229205 | P59: 2349983 | Q59: 2519980 | R59: 2415134 | S59: 2238950 | T59: 2268478 | U59: 2082406 | V59: 1912597 | W59: 2072555 | X59: 1785716 | Y59: 1634799 | Z59: 1096201 | AA59: 992417 | AB59: 1179737 | AC59: 1100196 | AD59: 961026 | AE59: 988279 | AF59: 1122560 | AG59: 1085642 | AH59: 1041846 | AI59: 907260 | AJ59: 867397 | AK59: 839450 | AL59: 850640 | AM59: 884699 | AN59: 849714 | AO59: 809440 | AP59: 773092 | AQ59: 770879 | AR59: 793680 | AS59: 715129 | AT59: 648778 | AU59: 665003 | AV59: 649166 | AW59: 615998 | AX59: 603030 | AY59: 597930 | AZ59: 580198 | BA59: 403421 | BB59: 554747 | BC59: 563997 | BD59: 594238 | BE59: 616422 | BF59: 606019 | BG59: 562064 | BH59: 471626 | BI59: 502867 | BJ59: 524533 | BK59: 514538 | BL59: 413420 | BM59: 504154
...

Sheet Intermediate (old)
A1: dataset: | B1: sedsQ | C1: sedsQ | D1: sedsQ | E1: sedsQ | H1: emissions
B2: CLTCB | C2: PATCB | D2: NGTCB | E2: RETCB | H2: CO2 Emissions
A3: Original Description | B3: =IF(ISERROR(VLOOKUP(B$2,code,2,)),"",VLOOKUP(B$2,code,2,)) -> Coal total consumption | C3: =IF(ISERROR(VLOOKUP(C$2,code,2,)),"",VLOOKUP(C$2,code,2,)) -> All petroleum products total consumption | D3: =IF(ISERROR(VLOOKUP(D$2,code,2,)),"",VLOOKUP(D$2,code,2,)) -> Natural gas total consumption (including supplemental gaseous fuels) | E3: =IF(ISERROR(VLOOKUP(E$2,code,2,)),"",VLOOKUP(E$2,code,2,)) -> Renewable energy total consumption | G3: =IF(ISERROR(VLOOKUP(G$2,code,2,)),"",VLOOKUP(G$2,code,2,)) | I3: =IF(ISERROR(VLOOKUP(I$2,code,2,)),"",VLOOKUP(I$2,code,2,)) | J3: =IF(ISERROR(VLOOKUP(J$2,code,2,)),"",VLOOKUP(J$2,code,2,)) | K3: =IF(ISERROR(VLOOKUP(K$2,code,2,)),"",VLOOKUP(K$2,code,2,)) | L3: =IF(ISERROR(VLOOKUP(L$2,code,2,)),"",VLOOKUP(L$2,code,2,)) | M3: =IF(ISERROR(VLOOKUP(M$2,code,2,)),"",VLOOKUP(M$2,code,2,)) | N3: =IF(ISERROR(VLOOKUP(N$2,code,2,)),"",VLOOKUP(N$2,code,2,)) | O3: =IF(ISERROR(VLOOKUP(O$2,code,2,)),"",VLOOKUP(O$2,code,2,)) | P3: =IF(ISERROR(VLOOKUP(P$2,code,2,)),"",VLOOKUP(P$2,code,2,)) | ... AR3: =IF(ISERROR(VLOOKUP(AR$2,code,2,)),"",VLOOKUP(AR$2,code,2,))
A5: outgoing ID:
B9: Primary Energy Quantities
B10: Coal | C10: Oil | D10: Natural Gas | E10: Renewables | G10: Total Fossil | H10: Total emssions | I10: Carbon intensity of fossil energy
A11: Units | B11: =VLOOKUP(B$2,code,3,) -> Billion Btu | C11: =VLOOKUP(C$2,code,3,) -> Billion Btu | D11: =VLOOKUP(D$2,code,3,) -> Billion Btu
A12: Year/Average | B12: =AVERAGE(B13:B64) -> 17433425 | C12: =AVERAGE(C13:C64) -> 35332071 | D12: =AVERAGE(D13:D64) -> 22904890 | E12: =AVERAGE(E13:E64) -> 6827001 | G12: =AVERAGE(G13:G64) -> 75670386 | H12: =AVERAGE(H13:H64) -> #DIV/0! | I12: =AVERAGE(I13:I64) -> #DIV/0!
A13: 1970 | B13: =IF(ISERROR(VLOOKUP(B$2,INDIRECT(B$1),MATCH($A13,INDIRECT(B$1&"_col"),),)),"",VLOOKUP(B$2,INDIRECT(B$1),MATCH($A13,INDIRECT(B$1&"_col"),),)) -> 12268895 | C13: =IF(ISERROR(VLOOKUP(C$2,INDIRECT(C$1),MATCH($A13,INDIRECT(C$1&"_col"),),)),"",VLOOKUP(C$2,INDIRECT(C$1),MATCH($A13,INDIRECT(C$1&"_col"),),)) -> 29500112 | D13: =IF(ISERROR(VLOOKUP(D$2,INDIRECT(D$1),MATCH($A13,INDIRECT(D$1&"_col"),),)),"",VLOOKUP(D$2,INDIRECT(D$1),MATCH($A13,INDIRECT(D$1&"_col"),),)) -> 21692710 | E13: =IF(ISERROR(VLOOKUP(E$2,INDIRECT(E$1),MATCH($A13,INDIRECT(E$1&"_col"),),)),"",VLOOKUP(E$2,INDIRECT(E$1),MATCH($A13,INDIRECT(E$1&"_col"),),)) -> 4070021 | G13: =SUM(B13:D13) -> 63461717 | H13: =IF(ISERROR(VLOOKUP(A13,INDIRECT($H$1),MATCH($H$2,INDIRECT($H$1&"_col"),),)),"",VLOOKUP(A13,INDIRECT($H$1),MATCH($H$2,INDIRECT($H$1&"_col"),),)) | I13: =IF(ISERROR(H13/G13),"",H13/G13)
A14: =A13+1 -> 1971 | B14: =IF(ISERROR(VLOOKUP(B$2,INDIRECT(B$1),MATCH($A14,INDIRECT(B$1&"_col"),),)),"",VLOOKUP(B$2,INDIRECT(B$1),MATCH($A14,INDIRECT(B$1&"_col"),),)) -> 11603202 | C14: =IF(ISERROR(VLOOKUP(C$2,INDIRECT(C$1),MATCH($A14,INDIRECT(C$1&"_col"),),)),"",VLOOKUP(C$2,INDIRECT(C$1),MATCH($A14,INDIRECT(C$1&"_col"),),)) -> 30541454 | D14: =IF(ISERROR(VLOOKUP(D$2,INDIRECT(D$1),MATCH($A14,INDIRECT(D$1&"_col"),),)),"",VLOOKUP(D$2,INDIRECT(D$1),MATCH($A14,INDIRECT(D$1&"_col"),),)) -> 22365248 | E14: =IF(ISERROR(VLOOKUP(E$2,INDIRECT(E$1),MATCH($A14,INDIRECT(E$1&"_col"),),)),"",VLOOKUP(E$2,INDIRECT(E$1),MATCH($A14,INDIRECT(E$1&"_col"),),)) -> 4262212 | G14: =SUM(B14:D14) -> 64509904 | H14: =IF(ISERROR(VLOOKUP(A14,INDIRECT($H$1),MATCH($H$2,INDIRECT($H$1&"_col"),),)),"",VLOOKUP(A14,INDIRECT($H$1),MATCH($H$2,INDIRECT($H$1&"_col"),),)) | I14: =IF(ISERROR(H14/G14),"",H14/G14) | K14: Growth Rate Calculation
A15: =A14+1 -> 1972 | B15: =IF(ISERROR(VLOOKUP(B$2,INDIRECT(B$1),MATCH($A15,INDIRECT(B$1&"_col"),),)),"",VLOOKUP(B$2,INDIRECT(B$1),MATCH($A15,INDIRECT(B$1&"_col"),),)) -> 12109530 | C15: =IF(ISERROR(VLOOKUP(C$2,INDIRECT(C$1),MATCH($A15,INDIRECT(C$1&"_col"),),)),"",VLOOKUP(C$2,INDIRECT(C$1),MATCH($A15,INDIRECT(C$1&"_col"),),)) -> 32919160 | D15: =IF(ISERROR(VLOOKUP(D$2,INDIRECT(D$1),MATCH($A15,INDIRECT(D$1&"_col"),),)),"",VLOOKUP(D$2,INDIRECT(D$1),MATCH($A15,INDIRECT(D$1&"_col"),),)) -> 22682497 | E15: =IF(ISERROR(VLOOKUP(E$2,INDIRECT(E$1),MATCH($A15,INDIRECT(E$1&"_col"),),)),"",VLOOKUP(E$2,INDIRECT(E$1),MATCH($A15,INDIRECT(E$1&"_col"),),)) -> 4382009 | G15: =SUM(B15:D15) -> 67711187 | H15: =IF(ISERROR(VLOOKUP(A15,INDIRECT($H$1),MATCH($H$2,INDIRECT($H$1&"_col"),),)),"",VLOOKUP(A15,INDIRECT($H$1),MATCH($H$2,INDIRECT($H$1&"_col"),),)) | I15: =IF(ISERROR(H15/G15),"",H15/G15) | K15: Annual: | L15: {=LOGEST(I16:I64)} -> #VALUE!
A16: =A15+1 -> 1973 | B16: =IF(ISERROR(VLOOKUP(B$2,INDIRECT(B$1),MATCH($A16,INDIRECT(B$1&"_col"),),)),"",VLOOKUP(B$2,INDIRECT(B$1),MATCH($A16,INDIRECT(B$1&"_col"),),)) -> 12960121 | C16: =IF(ISERROR(VLOOKUP(C$2,INDIRECT(C$1),MATCH($A16,INDIRECT(C$1&"_col"),),)),"",VLOOKUP(C$2,INDIRECT(C$1),MATCH($A16,INDIRECT(C$1&"_col"),),)) -> 34806025 | D16: =IF(ISERROR(VLOOKUP(D$2,INDIRECT(D$1),MATCH($A16,INDIRECT(D$1&"_col"),),)),"",VLOOKUP(D$2,INDIRECT(D$1),MATCH($A16,INDIRECT(D$1&"_col"),),)) -> 22595346 | E16: =IF(ISERROR(VLOOKUP(E$2,INDIRECT(E$1),MATCH($A16,INDIRECT(E$1&"_col"),),)),"",VLOOKUP(E$2,INDIRECT(E$1),MATCH($A16,INDIRECT(E$1&"_col"),),)) -> 4410938 | G16: =SUM(B16:D16) -> 70361492 | H16: =IF(ISERROR(VLOOKUP(A16,INDIRECT($H$1),MATCH($H$2,INDIRECT($H$1&"_col"),),)),"",VLOOKUP(A16,INDIRECT($H$1),MATCH($H$2,INDIRECT($H$1&"_col"),),)) | I16: =IF(ISERROR(H16/G16),"",H16/G16) | K16: 10 Year: | L16: =L15^10-1 -> #VALUE!
A17: =A16+1 -> 1974 | B17: =IF(ISERROR(VLOOKUP(B$2,INDIRECT(B$1),MATCH($A17,INDIRECT(B$1&"_col"),),)),"",VLOOKUP(B$2,INDIRECT(B$1),MATCH($A17,INDIRECT(B$1&"_col"),),)) -> 12651009 | C17: =IF(ISERROR(VLOOKUP(C$2,INDIRECT(C$1),MATCH($A17,INDIRECT(C$1&"_col"),),)),"",VLOOKUP(C$2,INDIRECT(C$1),MATCH($A17,INDIRECT(C$1&"_col"),),)) -> 33420613 | D17: =IF(ISERROR(VLOOKUP(D$2,INDIRECT(D$1),MATCH($A17,INDIRECT(D$1&"_col"),),)),"",VLOOKUP(D$2,INDIRECT(D$1),MATCH($A17,INDIRECT(D$1&"_col"),),)) -> 21729561 | E17: =IF(ISERROR(VLOOKUP(E$2,INDIRECT(E$1),MATCH($A17,INDIRECT(E$1&"_col"),),)),"",VLOOKUP(E$2,INDIRECT(E$1),MATCH($A17,INDIRECT(E$1&"_col"),),)) -> 4741851 | G17: =SUM(B17:D17) -> 67801183 | H17: =IF(ISERROR(VLOOKUP(A17,INDIRECT($H$1),MATCH($H$2,INDIRECT($H$1&"_col"),),)),"",VLOOKUP(A17,INDIRECT($H$1),MATCH($H$2,INDIRECT($H$1&"_col"),),)) | I17: =IF(ISERROR(H17/G17),"",H17/G17)
A18: =A17+1 -> 1975 | B18: =IF(ISERROR(VLOOKUP(B$2,INDIRECT(B$1),MATCH($A18,INDIRECT(B$1&"_col"),),)),"",VLOOKUP(B$2,INDIRECT(B$1),MATCH($A18,INDIRECT(B$1&"_col"),),)) -> 12655613 | C18: =IF(ISERROR(VLOOKUP(C$2,INDIRECT(C$1),MATCH($A18,INDIRECT(C$1&"_col"),),)),"",VLOOKUP(C$2,INDIRECT(C$1),MATCH($A18,INDIRECT(C$1&"_col"),),)) -> 32698781 | D18: =IF(ISERROR(VLOOKUP(D$2,INDIRECT(D$1),MATCH($A18,INDIRECT(D$1&"_col"),),)),"",VLOOKUP(D$2,INDIRECT(D$1),MATCH($A18,INDIRECT(D$1&"_col"),),)) -> 19977076 | E18: =IF(ISERROR(VLOOKUP(E$2,INDIRECT(E$1),MATCH($A18,INDIRECT(E$1&"_col"),),)),"",VLOOKUP(E$2,INDIRECT(E$1),MATCH($A18,INDIRECT(E$1&"_col"),),)) -> 4687119 | G18: =SUM(B18:D18) -> 65331470 | H18: =IF(ISERROR(VLOOKUP(A18,INDIRECT($H$1),MATCH($H$2,INDIRECT($H$1&"_col"),),)),"",VLOOKUP(A18,INDIRECT($H$1),MATCH($H$2,INDIRECT($H$1&"_col"),),)) | I18: =IF(ISERROR(H18/G18),"",H18/G18)
